Traceback (most recent call last):
  File "/opt/hostedtoolcache/Python/3.7.10/x64/lib/python3.7/site-packages/jupyter_cache/executors/utils.py", line 56, in single_nb_execution
    record_timing=False,
  File "/opt/hostedtoolcache/Python/3.7.10/x64/lib/python3.7/site-packages/nbclient/client.py", line 1112, in execute
    return NotebookClient(nb=nb, resources=resources, km=km, **kwargs).execute()
  File "/opt/hostedtoolcache/Python/3.7.10/x64/lib/python3.7/site-packages/nbclient/util.py", line 74, in wrapped
    return just_run(coro(*args, **kwargs))
  File "/opt/hostedtoolcache/Python/3.7.10/x64/lib/python3.7/site-packages/nbclient/util.py", line 53, in just_run
    return loop.run_until_complete(coro)
  File "/opt/hostedtoolcache/Python/3.7.10/x64/lib/python3.7/asyncio/base_events.py", line 587, in run_until_complete
    return future.result()
  File "/opt/hostedtoolcache/Python/3.7.10/x64/lib/python3.7/site-packages/nbclient/client.py", line 554, in async_execute
    cell, index, execution_count=self.code_cells_executed + 1
  File "/opt/hostedtoolcache/Python/3.7.10/x64/lib/python3.7/site-packages/nbclient/client.py", line 857, in async_execute_cell
    self._check_raise_for_error(cell, exec_reply)
  File "/opt/hostedtoolcache/Python/3.7.10/x64/lib/python3.7/site-packages/nbclient/client.py", line 760, in _check_raise_for_error
    raise CellExecutionError.from_cell_and_msg(cell, exec_reply_content)
nbclient.exceptions.CellExecutionError: An error occurred while executing the following cell:
------------------
# Importando paquetes

### Librer√≠a de manipulaci√≥n de datos 
import pandas as pd
pd.set_option('display.max_columns', 50)
pd.options.mode.chained_assignment = None  # default='warn'
pd.options.display.float_format = '{:,.2f}'.format

### Librer√≠a de √°lgebra
import numpy as np

### Librer√≠as para graficar
import matplotlib.pyplot as plt
import matplotlib.image as mpimg
import matplotlib as mpl

### Customizamos para tener fondos transparentes con alta resoluci√≥n
mpl.rcParams['figure.dpi']= 300
mpl.rc("savefig", dpi=300)
plt.rcParams.update({
    "figure.facecolor":  (0.0, 0.0, 0.0, 0.0),
    "axes.facecolor":    (0.0, 0.0, 0.0, 0.0),
    "savefig.facecolor": (0.0, 0.0, 0.0, 0.0),
})
plt.rc('axes.spines', **{'bottom':True, 'left':True, 'right':False, 'top':False})

### Para formato local
import locale
try:
    ### Windows
    locale.setlocale(locale.LC_ALL, 'esp')
except Error:
    ### Ubuntu (para action)
    locale.setlocale(locale.LC_ALL, 'es_ES.utf8')

### Otros paquetes
import math
import os
import json as json
import datetime
import time
import IPython.display as display
from PIL import Image, ImageDraw, ImageFont
from IPython.display import display, HTML

### Solo de uso espor√°dico
import csv
from io import StringIO
import pkg_resources
import types

### Gracias a joelostblom (https://gitlab.com/joelostblom/session_info)
import session_info

### Pybtex
import pybtex.plugin
------------------

[0;31m---------------------------------------------------------------------------[0m
[0;31mError[0m                                     Traceback (most recent call last)
[0;32m<ipython-input-1-14f945b14481>[0m in [0;36m<module>[0;34m[0m
[1;32m     30[0m     [0;31m### Windows[0m[0;34m[0m[0;34m[0m[0;34m[0m[0m
[0;32m---> 31[0;31m     [0mlocale[0m[0;34m.[0m[0msetlocale[0m[0;34m([0m[0mlocale[0m[0;34m.[0m[0mLC_ALL[0m[0;34m,[0m [0;34m'esp'[0m[0;34m)[0m[0;34m[0m[0;34m[0m[0m
[0m[1;32m     32[0m [0;32mexcept[0m [0mError[0m[0;34m:[0m[0;34m[0m[0;34m[0m[0m

[0;32m/opt/hostedtoolcache/Python/3.7.10/x64/lib/python3.7/locale.py[0m in [0;36msetlocale[0;34m(category, locale)[0m
[1;32m    607[0m         [0mlocale[0m [0;34m=[0m [0mnormalize[0m[0;34m([0m[0m_build_localename[0m[0;34m([0m[0mlocale[0m[0;34m)[0m[0;34m)[0m[0;34m[0m[0;34m[0m[0m
[0;32m--> 608[0;31m     [0;32mreturn[0m [0m_setlocale[0m[0;34m([0m[0mcategory[0m[0;34m,[0m [0mlocale[0m[0;34m)[0m[0;34m[0m[0;34m[0m[0m
[0m[1;32m    609[0m [0;34m[0m[0m

[0;31mError[0m: unsupported locale setting

During handling of the above exception, another exception occurred:

[0;31mNameError[0m                                 Traceback (most recent call last)
[0;32m<ipython-input-1-14f945b14481>[0m in [0;36m<module>[0;34m[0m
[1;32m     30[0m     [0;31m### Windows[0m[0;34m[0m[0;34m[0m[0;34m[0m[0m
[1;32m     31[0m     [0mlocale[0m[0;34m.[0m[0msetlocale[0m[0;34m([0m[0mlocale[0m[0;34m.[0m[0mLC_ALL[0m[0;34m,[0m [0;34m'esp'[0m[0;34m)[0m[0;34m[0m[0;34m[0m[0m
[0;32m---> 32[0;31m [0;32mexcept[0m [0mError[0m[0;34m:[0m[0;34m[0m[0;34m[0m[0m
[0m[1;32m     33[0m     [0;31m### Ubuntu (para action)[0m[0;34m[0m[0;34m[0m[0;34m[0m[0m
[1;32m     34[0m     [0mlocale[0m[0;34m.[0m[0msetlocale[0m[0;34m([0m[0mlocale[0m[0;34m.[0m[0mLC_ALL[0m[0;34m,[0m [0;34m'es_ES.utf8'[0m[0;34m)[0m[0;34m[0m[0;34m[0m[0m

[0;31mNameError[0m: name 'Error' is not defined
NameError: name 'Error' is not defined

